2025-09-07 07:12:11,584 - notebook_01_highperf_dataset - INFO - 노트북 작업 시작: 01_highperf_dataset
2025-09-07 07:12:11,584 - notebook_01_highperf_dataset - INFO - 로그 디렉토리: notebooks/modular/unit_tests/01_highperf_dataset/20250907_071211
2025-09-07 07:12:39,384 - notebook_01_highperf_dataset - ERROR - 데이터프레임 저장 실패: class_distribution.csv: Cannot save file into a non-existent directory: 'notebooks/modular/unit_tests/01_highperf_dataset/20250907_071211/data'
Traceback (most recent call last):
  File "/home/ieyeppo/AI_Lab/computer-vision-competition-1SEN/src/logging/notebook_logger.py", line 225, in save_dataframe
    df.to_csv(filepath, index=False, encoding='utf-8-sig')
  File "/home/ieyeppo/.pyenv/versions/cv_py3_11_9/lib/python3.11/site-packages/pandas/util/_decorators.py", line 333, in wrapper
    return func(*args, **kwargs)
           ^^^^^^^^^^^^^^^^^^^^^
  File "/home/ieyeppo/.pyenv/versions/cv_py3_11_9/lib/python3.11/site-packages/pandas/core/generic.py", line 3986, in to_csv
    return DataFrameRenderer(formatter).to_csv(
           ^^^^^^^^^^^^^^^^^^^^^^^^^^^^^^^^^^^^
  File "/home/ieyeppo/.pyenv/versions/cv_py3_11_9/lib/python3.11/site-packages/pandas/io/formats/format.py", line 1014, in to_csv
    csv_formatter.save()
  File "/home/ieyeppo/.pyenv/versions/cv_py3_11_9/lib/python3.11/site-packages/pandas/io/formats/csvs.py", line 251, in save
    with get_handle(
         ^^^^^^^^^^^
  File "/home/ieyeppo/.pyenv/versions/cv_py3_11_9/lib/python3.11/site-packages/pandas/io/common.py", line 749, in get_handle
    check_parent_directory(str(handle))
  File "/home/ieyeppo/.pyenv/versions/cv_py3_11_9/lib/python3.11/site-packages/pandas/io/common.py", line 616, in check_parent_directory
    raise OSError(rf"Cannot save file into a non-existent directory: '{parent}'")
OSError: Cannot save file into a non-existent directory: 'notebooks/modular/unit_tests/01_highperf_dataset/20250907_071211/data'
2025-09-07 07:12:58,670 - notebook_01_highperf_dataset - ERROR - 그림 저장 실패: 고품질_샘플_라벨_16.png: [Errno 2] No such file or directory: 'notebooks/modular/unit_tests/01_highperf_dataset/20250907_071211/images/고품질_샘플_라벨_16.png'
Traceback (most recent call last):
  File "/home/ieyeppo/AI_Lab/computer-vision-competition-1SEN/src/logging/notebook_logger.py", line 187, in save_figure
    fig.savefig(filepath, dpi=dpi, bbox_inches='tight', facecolor='white')  # 그림 파일 저장
    ^^^^^^^^^^^^^^^^^^^^^^^^^^^^^^^^^^^^^^^^^^^^^^^^^^^^^^^^^^^^^^^^^^^^^^
  File "/home/ieyeppo/.pyenv/versions/cv_py3_11_9/lib/python3.11/site-packages/matplotlib/figure.py", line 3490, in savefig
    self.canvas.print_figure(fname, **kwargs)
  File "/home/ieyeppo/.pyenv/versions/cv_py3_11_9/lib/python3.11/site-packages/matplotlib/backend_bases.py", line 2186, in print_figure
    result = print_method(
             ^^^^^^^^^^^^^
  File "/home/ieyeppo/.pyenv/versions/cv_py3_11_9/lib/python3.11/site-packages/matplotlib/backend_bases.py", line 2042, in <lambda>
    print_method = functools.wraps(meth)(lambda *args, **kwargs: meth(
                                                                 ^^^^^
  File "/home/ieyeppo/.pyenv/versions/cv_py3_11_9/lib/python3.11/site-packages/matplotlib/backends/backend_agg.py", line 481, in print_png
    self._print_pil(filename_or_obj, "png", pil_kwargs, metadata)
  File "/home/ieyeppo/.pyenv/versions/cv_py3_11_9/lib/python3.11/site-packages/matplotlib/backends/backend_agg.py", line 430, in _print_pil
    mpl.image.imsave(
  File "/home/ieyeppo/.pyenv/versions/cv_py3_11_9/lib/python3.11/site-packages/matplotlib/image.py", line 1657, in imsave
    image.save(fname, **pil_kwargs)
  File "/home/ieyeppo/.pyenv/versions/cv_py3_11_9/lib/python3.11/site-packages/PIL/Image.py", line 2428, in save
    fp = builtins.open(filename, "w+b")
         ^^^^^^^^^^^^^^^^^^^^^^^^^^^^^^
FileNotFoundError: [Errno 2] No such file or directory: 'notebooks/modular/unit_tests/01_highperf_dataset/20250907_071211/images/고품질_샘플_라벨_16.png'
